<?xml version="1.0"?>
<robot name="bulldog_wheel" xmlns:xacro="http://ros.org/wiki/xacro">

  <!-- <xacro:include filename="$(find bulldog_description)/urdf/bulldog/inertial_macros.xacro" /> -->

  <xacro:property name="wheel_length" value="0.142" />
  <xacro:property name="wheel_radius" value="0.183" />

  <xacro:macro name="bulldog_wheel" params="wheel_prefix *joint_pose">

  <link name="${wheel_prefix}_wheel_link">
    <inertial>
      <mass value="3" />
      <origin xyz="0 0 0" />
      <inertia  ixx="0.025" ixy="0" ixz="0" iyy="0.025" iyz="0" izz="0.045" />
    </inertial>
    <!-- <xacro:inertial_cylinder mass="3" length="${wheel_length}" radius="${wheel_radius}">
      <origin xyz="0 0 0"/>
    </xacro:inertial_cylinder> -->
    <visual>
      <origin xyz="0 0 0" rpy="0 0 0" />
      <geometry>
        <mesh filename="file:///$(find bulldog_description)/meshes/wheel.stl" />
      </geometry>
      <material name="dark_grey" />
    </visual>
    <collision>
      <origin xyz="0 0 0" rpy="${M_PI/2} 0 0" />
      <geometry>
        <cylinder length="${wheel_length}" radius="${wheel_radius}" />
      </geometry>
    </collision>
  </link>

  <gazebo reference="${wheel_prefix}_wheel_link">
    <mu1 value="1.0"/>
    <mu2 value="0.2"/>
    <!-- <mu2 value="0.25"/> KEMPES engineers year-book 1985 (90th edition) -->
    <kp value="10000000.0" />
    <kd value="1.0" />
    <fdir1 value="1 0 0"/>
    <material>Gazebo/DarkGrey</material>
  </gazebo>

  <joint name="${wheel_prefix}_wheel_joint" type="continuous">
    <parent link="base_link"/>
    <child link="${wheel_prefix}_wheel_link"/>
    <xacro:insert_block name="joint_pose"/>
    <axis xyz="0 1 0" rpy="0 0 0" />
  </joint>

  <transmission name="${wheel_prefix}_wheel_trans" type="SimpleTransmission">
    <type>transmission_interface/SimpleTransmission</type>
    <actuator name="${wheel_prefix}_wheel_motor">
      <mechanicalReduction>1</mechanicalReduction>
    </actuator>
    <joint name="${wheel_prefix}_wheel_joint">
      <hardwareInterface>VelocityJointInterface</hardwareInterface>
    </joint>
  </transmission>

  </xacro:macro>
</robot>
