<?xml version="1.0"?>
<robot xmlns:xacro="http://ros.org/wiki/xacro" name="robot_base" >

    <xacro:include filename="robot_essentials.xacro"/>

    <link name="base_link">
        <visual>
            <origin xyz="0 0 0" rpy="1.5707963267949 0 3.14"/>
            <geometry>
                <mesh filename="package://articubot_one/meshes/robot_base.stl"/>
            </geometry>
            <material name="">
                <color rgba="0.79216 0.81961 0.93333 1"/>
            </material>
        </visual>
    </link>

    <!-- Ruedas -->
    <!-- <xacro:robot_wheel prefix="front_left"/>
    <xacro:robot_wheel prefix="front_right"/>
    <xacro:robot_wheel prefix="rear_left"/>
    <xacro:robot_wheel prefix="rear_right"/> -->

    <!-- Articulaciones de ruedas -->
    <!-- <xacro:wheel_joint prefix="front_left" origin="0.220 0.250 0"/>
    <xacro:wheel_joint prefix="front_right" origin="0.220 -0.250 0"/>
    <xacro:wheel_joint prefix="rear_left" origin="-0.220 0.250 0"/>
    <xacro:wheel_joint prefix="rear_right" origin="-0.220 -0.250 0"/> -->

    <!-- WHEELS -->
    <!-- Fron left wheel -->
    <link name="front_left_wheel">
        <visual>
            <origin
            xyz="0 0 0"
            rpy="0 0 0" />
            <geometry>
                <mesh filename="package://articubot_one/meshes/wheel.stl" />
            </geometry>
            <material name="">
                <color rgba="0.79216 0.81961 0.93333 1" />
            </material>
        </visual>
    </link>

    <joint name="front_left_wheel_joint" type="continuous">
        <axis xyz="0 0 1"/>
        <parent link ="base_link"/>
        <child link ="front_left_wheel"/>
        <origin rpy ="${-pi/2} 0 0" xyz= "0.220 0.250 0"/>
  </joint>

  <!-- Front right wheel -->
    <link name="front_right_wheel">
        <visual>
            <origin
            xyz="0 0 0"
            rpy="0 0 0" />
            <geometry>
                <mesh filename="package://articubot_one/meshes/wheel.stl" />
            </geometry>
            <material name="">
                <color rgba="0.79216 0.81961 0.93333 1" />
            </material>
        </visual>
    </link>

    <joint name="front_right_wheel_joint" type="continuous">
        <axis xyz="0 0 -1"/>
        <parent link ="base_link"/>
        <child link ="front_right_wheel"/>
        <origin rpy ="${pi/2} 0 0" xyz= "0.220 -0.250 0"/>
  </joint>

  <!-- Rear left wheel -->
    <link name="rear_left_wheel">
        <visual>
            <origin
            xyz="0 0 0"
            rpy="0 0 0" />
            <geometry>
                <mesh filename="package://articubot_one/meshes/wheel.stl" />
            </geometry>
            <material name="">
                <color rgba="0.79216 0.81961 0.93333 1" />
            </material>
        </visual>
    </link>

    <joint name="rear_left_wheel_joint" type="continuous">
        <axis xyz="0 0 1"/>
        <parent link ="base_link"/>
        <child link ="rear_left_wheel"/>
        <origin rpy ="${-pi/2} 0 0" xyz= "-0.220 0.250 0"/>
  </joint>

  <!-- Rear right wheel -->
    <link name="rear_right_wheel">
        <visual>
            <origin
            xyz="0 0 0"
            rpy="0 0 0" />
            <geometry>
                <mesh filename="package://articubot_one/meshes/wheel.stl" />
            </geometry>
            <material name="">
                <color rgba="0.79216 0.81961 0.93333 1" />
            </material>
        </visual>
    </link>

    <joint name="rear_right_wheel_joint" type="continuous">
        <axis xyz="0 0 -1"/>
        <parent link ="base_link"/>
        <child link ="rear_right_wheel"/>
        <origin rpy ="${pi/2} 0 0" xyz= "-0.220 -0.250 0"/>
  </joint>

</robot>