<?xml version="1.0"?>
<robot xmlns:xacro="http://www.ros.org/wiki/xacro">

<!-- Macro para las ruedas -->
<xacro:macro name="robot_wheel" params="prefix">
    <link name="${prefix}_wheel">
        <visual>
            <origin
            xyz="0 0 0"
            rpy="1.5707963267949 0 0" />
            <geometry>
                <mesh filename="package://articubot_one/meshes/wheel.stl" />
            </geometry>
            <material name="">
                <color rgba="0.79216 0.81961 0.93333 1" />
            </material>
        </visual>
    </link>
</xacro:macro>

<!-- Macro para las articulaciones de las ruedas -->
<xacro:macro name="wheel_joint" params="prefix origin">
  <joint name="${prefix}_wheel_joint" type="continuous">
    <axis xyz="0 1 0"/>
    <parent link ="base_link"/>
    <child link ="${prefix}_wheel"/>
    <origin rpy ="0 0 0" xyz= "${origin}"/>
  </joint>
</xacro:macro>

<!-- Macros para las INERCIAS -->
<xacro:macro name="inertial_box" params="mass x y z *origin">
    <inertial>
        <xacro:insert_block name="origin"/>
        <mass value="${mass}" />
        <inertia ixx="${(1/12) * mass * (y*y+z*z)}" ixy="0.0" ixz="0.0"
                iyy="${(1/12) * mass * (x*x+z*z)}" iyz="0.0"
                izz="${(1/12) * mass * (x*x+y*y)}" />
    </inertial>
</xacro:macro>


<xacro:macro name="inertial_cylinder" params="mass length radius *origin">
    <inertial>
        <xacro:insert_block name="origin"/>
        <mass value="${mass}" />
        <inertia ixx="${(1/12) * mass * (3*radius*radius + length*length)}" ixy="0.0" ixz="0.0"
                iyy="${(1/12) * mass * (3*radius*radius + length*length)}" iyz="0.0"
                izz="${(1/2) * mass * (radius*radius)}" />
    </inertial>
</xacro:macro>

</robot>